Workbook

Sheet LEIA_ME
B2: Diagnóstico e normalização do checklist de faturamento
B4: Origem | C4: Arquivo "F2_Preenchimento_checklist - FINANCEIRO_DP_OPERAÇÃO_DOCUMENTAÇÃO_FATURAMENTO", enviado pela DAF.
B5: Base analisada | C5: 176 linhas úteis, 8 contratos (BNB, CEF, DOCAS, SEFAZ RS, SESCOOP, TERRACAP, TJ CE, Telebrás), 3 áreas responsáveis.
B6: Objetivo | C6: Transformar o checklist atual em uma matriz de exigibilidade computável, que possa ser lida por um sistema de conferência automática de documentação de faturamento.
B7: O que foi feito | C7: 1) Catálogo canônico de tipos documentais, consolidando 69 nomenclaturas distintas em 51 tipos reais. 2) Normalização das 176 linhas contra esse catálogo. 3) Detecção automática de divergências (duplicidade, competência incoerente, campo em branco, pasta incompatível, linha composta). 4) Proposta dos campos que faltam no checklist para viabilizar a automação.
B8: Como usar | C8: Revisar as abas na ordem: DIAGNOSTICO → CATALOGO_DOCUMENTOS → MATRIZ_EXIGIBILIDADE → DIVERGENCIAS_POR_LINHA. As células em AMARELO são decisões que dependem da área de negócio e não podem ser inferidas do arquivo.
B9: Status | C9: Documento de trabalho. Nenhuma conclusão aqui substitui a leitura do edital/contrato de cada cliente.
B11: PREMISSAS ADOTADAS
B12: P1 | C12: FGTS, DCTFWeb/DARF e INSS de uma competência são recolhidos no mês seguinte; portanto a competência-referência desses documentos é sempre M-1. Divergências no arquivo foram sinalizadas com base nessa regra.
B13: P2 | C13: Contratos públicos: a exigência documental decorre do edital/contrato e do art. 121 da Lei 14.133/2021 (responsabilidade subsidiária). O campo "PREVISÃO = Edital" não identifica a cláusula — isso foi marcado como lacuna.
B14: P3 | C14: A criticidade sugerida ("Bloqueante" / "Não bloqueante") é proposta técnica e precisa ser validada contrato a contrato antes de virar regra de bloqueio no sistema.
B15: P4 | C15: Granularidade (por contrato x por profissional) foi inferida da natureza do documento, não do arquivo original, que não possui esse campo.
B16: P5 | C16: Nenhum dado pessoal de colaborador foi utilizado: o arquivo contém apenas metadados de tipos documentais.
B18: LEGENDA
B19: Amarelo | C19: Campo a preencher/decidir pela área de negócio
B20: Laranja | C20: Divergência que impede a automação enquanto não for corrigida
B21: Verde | C21: Campo derivado da normalização, já preenchido

Sheet DIAGNOSTICO
A1: ID | B1: Severidade | C1: Achado | D1: Evidência no arquivo | E1: Impacto no faturamento | F1: Ação recomendada
A2: D01 | B2: Crítica | C2: A nomenclatura não é chave confiável: 69 códigos para 51 tipos reais | D2: CND_CIVEL_E_CRIMINAL / CND_CÍVEL_E_CRIMINAL; RECIBO_DE_FERIAS / RECIBO_DE_FÉRIAS; COMPROVANTE_PG_RECSISÃO (erro de digitação); "NOTA _FISCAL" com espaço; GFD_GUIA_DO_FGTS / GFD-GUIA_DO_FGTS / GUIA_GFD / FGTS-DETALHE_DA_GUIA. | E2: Qualquer varredura automática de pastas por nome de arquivo falha ou gera falso "documento ausente". | F2: Adotar o catálogo canônico da aba CATALOGO_DOCUMENTOS como chave única, com os nomes atuais registrados como sinônimos (aliases) para reconhecimento do legado.
A3: D02 | B3: Crítica | C3: Falta a dimensão "evento" (mensal, 13º, férias, rescisão, admissão) | D3: TJ CE usa GFD_GUIA_DO_FGTS e DCTFWEB_DARF duas vezes — uma para a folha mensal e outra para o 13º — distinguíveis apenas pelo nome da pasta. SESCOOP usa GFD_GUIA_DO_FGTS para dois documentos diferentes ("Guia FGTS" e "FGTS Digital - Relatórios"). | E3: O sistema não consegue saber qual documento satisfaz qual exigência; o 13º e a folha mensal competem pela mesma linha do checklist. | F3: Criar campo EVENTO. A chave da exigência passa a ser: contrato + tipo canônico + evento + competência (+ profissional, quando individual).
A4: D03 | B4: Crítica | C4: Competência-referência incoerente entre contratos para o mesmo documento | D4: 8 linhas divergentes. COMPROVANTE_PG_FGTS e COMPROVANTE_PG_INSS constam como "Competência Anterior" em BNB, CEF, DOCAS e SESCOOP, mas como "Mês da Competência" em TJ CE. GFD_GUIA_DO_FGTS consta como "Mês da Competência" em BNB e DOCAS. | E4: O motor de conferência buscaria a guia da competência errada: cobra documento que ainda não existe ou aceita documento de mês indevido. Fonte direta de glosa. | F4: A defasagem é atributo do documento (obrigação legal), não do contrato. Fixar no catálogo: guia/DARF/comprovante de FGTS, INSS e IRRF = M-1. Corrigir as 8 linhas.
A5: D04 | B5: Alta | C5: Duplicidades e linhas concorrentes dentro do mesmo contrato | D5: 9 grupos: DOCAS tem CRF_FGTS duas vezes; TJ CE tem recibo e comprovante de férias duplicados com grafias diferentes; CEF e TJ CE têm o comprovante de rescisão em duas linhas, em pastas diferentes (RESCISÃO e OPERAÇÃO). | E5: Contagem de completude inflada e conferência em duplicidade pela equipe. | F5: Consolidar; manter uma linha por (contrato + tipo + evento).
A6: D05 | B6: Alta | C6: Linhas compostas: uma linha descreve mais de um artefato | D6: "VALE TRANSPORTE E COMPROVANTE DE PAGAMENTO OU TERMO DE NÃO ADESÃO" (3 artefatos + condicional); "CÓPIA DA DCTFWEB COMPLETO, RESPECTIVO DARF E COMPROVANTE DE PAGAMENTO" (3 artefatos); "VALE ALIMENTAÇÃO E COMPROVANTE DE PAGAMENTO". | E6: Não é possível marcar entrega parcial nem saber o que exatamente está faltando. | F6: Quebrar em uma linha por artefato e, para os condicionais, criar regra "A OU B" explícita.
A7: D06 | B7: Alta | C7: Prazo em texto livre, não computável | D7: 17 variantes para cerca de 10 regras: "ATÉ DIA 21" / "DIA 21" / "ATÉ O DIA 21"; "ATÉ O 5º DIA ÚTIL" / "5º DIA UTIL"; "10º dia útil" / "Até o 9º dia útil". | E7: Impossível calcular atraso, disparar alerta automático ou medir SLA por área. | F7: Estruturar em: âncora (início da competência / ateste / evento) + tipo de dia (útil/corrido) + limite. Já pré-preenchido na MATRIZ_EXIGIBILIDADE.
A8: D07 | B8: Alta | C8: Campos obrigatórios em branco no bloco mais recente | D8: PREVISÃO em branco em 28 linhas; periodicidade em branco em 26; 3 linhas sem contrato de origem (COMPROVANTE_PG_VT, COMPROVANTE_PG_VA_VR e XML) e sem descrição. | E8: As linhas órfãs se perdem em qualquer exportação; hoje só fazem sentido por herança visual da célula mesclada na planilha. | F8: Completar antes da carga inicial. Tornar os campos obrigatórios no cadastro do sistema.
A9: D08 | B9: Alta | C9: Seis nomes diferentes para o artefato que dispara o relógio D+3 | D9: AUTORIZAÇÃO_DE_FATURAMENTO, E-MAIL_AUTORIZAÇÃO_EMISSÃO_NF (duas grafias), TERMO_DE_RECEBIMENTO, TRD, além de relatórios/planilhas de medição com quatro nomes. | E9: A política institucional fixa "NF em até D+3 após o ateste formal", mas não existe um evento único e datado de ateste no checklist. O KPI não é apurável de forma objetiva. | F9: Criar o evento "ATESTE_REGISTRADO" com data, forma (sistema/e-mail/despacho) e evidência anexa. É o marco zero do D+3 e a base de todos os indicadores da política.
A10: D09 | B10: Alta | C10: Ausência de encargos e benefícios em três contratos | D10: TERRACAP, Telebrás e SEFAZ RS não têm nenhuma linha de folha, FGTS, INSS ou benefícios — apenas certidões e documentos de operação. | E10: Se esses contratos envolvem alocação de pessoas, há exposição direta a responsabilidade subsidiária e a glosa por falta de comprovação. | F10: Confirmar a natureza contratual (entrega de produto x posto de trabalho). Se houver alocação, a matriz está incompleta — prioridade máxima.
A11: D10 | B11: Média | C11: A tríade do plano de saúde não está completa em nenhum contrato | D11: Relação do plano: DOCAS, SESCOOP e TJ CE. Comprovante de pagamento do plano: apenas SESCOOP. Nenhum contrato exige explicitamente o cruzamento com o desconto na folha. | E11: Exatamente o cenário de conciliação descrito pela DAF hoje não é exigível nem verificável em 7 dos 8 contratos. | F11: Padronizar a tríade (relação + desconto em folha + comprovante de pagamento) como controle interno, mesmo onde o edital não exige.
A12: D11 | B12: Média | C12: Documento arquivado em família incompatível | D12: Comprovantes de parcelamento do INSS na pasta FGTS; relatórios do FGTS Digital na pasta PARCELAMENTOS; comprovante de rescisão na pasta OPERAÇÃO; INSS/FGTS do 13º na pasta 13º e no mesmo tipo do mensal. | E12: A varredura por pasta não encontra o documento no lugar esperado. | F12: Reorganizar segundo a família canônica; a pasta passa a ser derivada do tipo, não digitada.
... A16: D15 | B16: Média | C16: Exigência sem rastreabilidade da fonte | D16: "PREVISÃO = Edital" em 122 linhas, sem número de cláusula, item ou norma. | E16: Em questionamento do cliente ou de órgão de controle não há como demonstrar a origem da exigência, nem revisar a matriz após aditivo. | F16: Criar campo FUNDAMENTO (contrato, cláusula/item, ou norma) e vinculá-lo ao documento contratual.

Sheet CATALOGO_DOCUMENTOS
A1: COD_CANONICO | B1: NOME_OFICIAL | C1: FAMILIA | D1: GRANULARIDADE | E1: EVENTO | F1: COMPETENCIA_REFERENCIA | G1: FONTE_MESTRE | H1: CRITICIDADE_SUGERIDA | I1: CONTRATOS_QUE_EXIGEM | J1: NOMENCLATURAS_ATUAIS (aliases) | K1: FUNDAMENTO (preencher)
A2: OPE.RELATORIO_MEDICAO | B2: Relatório técnico de medição / atividades | C2: Operação e medição | D2: Contrato | E2: Mensal | F2: Mês da competência | G2: Operação | H2: Bloqueante | I2: BNB, DOCAS, SESCOOP, TERRACAP, TJ CE | J2: RELATORIO_DE_ATIVIDADES ; RELATORIO_DE_FATURAMENTO ; RELATÓRIO_DE_ATIVIDADES_DESENVOLVIDAS_POR _CADA_UM_DOS_POSTOS_DE_TRABALHO ; RELATÓRIO_DE_FATURAMENTO ; RTA_RELATORIO_TECNICO_ATIVIDADES_DE_FATURAMENTO
A3: OPE.PLANILHA_MEDICAO | B3: Planilha de faturamento (memória de cálculo) | C3: Operação e medição | D3: Contrato | E3: Mensal | F3: Mês da competência | G3: Operação | H3: Bloqueante | I3: TERRACAP, TJ CE, Telebrás | J3: PLANILHA_DE_FATURAMENTO
A4: OPE.AUTORIZACAO_FATURAMENTO | B4: Autorização formal de faturamento | C4: Operação e medição | D4: Contrato | E4: Mensal | F4: Mês da competência | G4: Operação | H4: Bloqueante | I4: BNB, DOCAS, TERRACAP, TJ CE, Telebrás | J4: AUTORIZAÇÃO_DE_FATURAMENTO ; E-MAIL_AUTORIZACAO_EMISSAO_NF ; E-MAIL_AUTORIZAÇÃO_EMISSÃO_NF
A5: OPE.ATESTE_RECEBIMENTO | B5: Ateste / Termo de recebimento do cliente | C5: Operação e medição | D5: Contrato | E5: Mensal | F5: Mês da competência | G5: Cliente | H5: Bloqueante | I5: SEFAZ RS, SESCOOP | J5: TERMO_DE_RECEBIMENTO ; TRD
A6: OPE.EMPENHO | B6: Nota de empenho vigente | C6: Operação e medição | D6: Contrato | E6: Mensal | F6: Mês da competência | G6: Cliente | H6: Bloqueante | I6: CEF | J6: EMPENHO
A7: OPE.RELACAO_ALOCADOS | B7: Relação de empregados alocados no contrato | C7: Operação e medição | D7: Contrato | E7: Mensal | F7: Mês da competência | G7: Operação | H7: Bloqueante | I7: CEF | J7: RELAÇÃO_DOS_EMPREGADOS_ALOCADOS_NO_CONTRATO_PARA_PRESTAÇÃO_DE_SERVIÇOS
A8: OPE.DOC_TECNICA | B8: Documentação técnica dos sistemas desenvolvidos | C8: Operação e medição | D8: Contrato | E8: Mensal | F8: Mês da competência | G8: Operação | H8: Não bloqueante | I8: DOCAS, SEFAZ RS | J8: DOCUMENTAÇÃO_TÉCNICA_DOS_SISTEMAS_DESENVOLVIDOS
A9: OPE.FOLHA_PONTO | B9: Folha de ponto / ponto eletrônico | C9: Operação e medição | D9: Profissional | E9: Mensal | F9: Mês da competência | G9: DP | H9: Bloqueante | I9: DOCAS | J9: FOLHAS_DE_PONTO
A10: OPE.MOVIMENTACAO_PESSOAL | B10: Movimentação de pessoal do contrato | C10: Operação e medição | D10: Contrato | E10: Eventual | F10: Mês da competência | G10: DP | H10: Não bloqueante | I10: TJ CE | J10: MOVIMENTACAO_DE_PESSOAL
A11: FIS.NOTA_FISCAL | B11: Nota fiscal de serviço | C11: Fiscal | D11: Contrato | E11: Mensal | F11: Mês da competência | G11: Financeiro | H11: Bloqueante | I11: BNB, CEF, DOCAS, SEFAZ RS, SESCOOP, TERRACAP, TJ CE, Telebrás | J11: NOTA _FISCAL ; NOTA_FISCAL
A12: FIS.NF_XML | B12: XML da nota fiscal | C12: Fiscal | D12: Contrato | E12: Mensal | F12: Mês da competência | G12: Financeiro | H12: Bloqueante | I12: Telebrás | J12: XML
A13: FIS.CARTA_ENTREGA_NF | B13: Carta de entrega da nota fiscal | C13: Fiscal | D13: Contrato | E13: Mensal | F13: Mês da competência | G13: Financeiro | H13: Bloqueante | I13: BNB, CEF, DOCAS, SEFAZ RS, SESCOOP, TERRACAP, TJ CE, Telebrás | J13: CARTA_NOTA_FISCAL
... A52: ADM.DOCUMENTACAO | B52: Documentação admissional | C52: Admissão | D52: Profissional | E52: Admissão | F52: Data do evento | G52: DP | H52: Bloqueante | I52: TJ CE | J52: DOC_ADMISSAO

Sheet MATRIZ_EXIGIBILIDADE
A1: ID | B1: CONTRATO | C1: COD_CANONICO | D1: DESCRICAO_ORIGINAL | E1: NOMENCLATURA_ORIGINAL | F1: FAMILIA | G1: EVENTO | H1: GRANULARIDADE | I1: CRITICIDADE | J1: RESPONSAVEL | K1: COMPETENCIA_ARQUIVO | L1: COMPETENCIA_CORRIGIDA | M1: PRAZO_ORIGINAL | N1: PRAZO_ANCORA | O1: PRAZO_TIPO_DIA | P1: PRAZO_LIMITE | Q1: REPOSITORIO | R1: PASTA | S1: PERIODICIDADE | T1: PREVISAO_ARQUIVO | U1: FUNDAMENTO (preencher) | V1: DIVERGENCIAS
A2: L001 | B2: BNB | C2: OPE.RELATORIO_MEDICAO | D2: Relatório de Faturamento | E2: RELATORIO_DE_FATURAMENTO | F2: Operação e medição | G2: Mensal | H2: Contrato | I2: Bloqueante | J2: OPERAÇÃO | K2: Mês da Competência | L2: Mês da competência | M2: SOB FATURAMENTO | N2: Ateste do cliente | O2: Corrido | P2: 0 | Q2: JIRA | S2: Mensalmente | T2: Até último dia útil
A3: L002 | B3: BNB | C3: OPE.AUTORIZACAO_FATURAMENTO | D3: Autorização de Faturamento | E3: AUTORIZAÇÃO_DE_FATURAMENTO | F3: Operação e medição | G3: Mensal | H3: Contrato | I3: Bloqueante | J3: OPERAÇÃO | K3: Mês da Competência | L3: Mês da competência | M3: SOB FATURAMENTO | N3: Ateste do cliente | O3: Corrido | P3: 0 | Q3: JIRA | S3: Mensalmente | T3: Até último dia útil
A4: L003 | B4: BNB | C4: FIS.CARTA_ENTREGA_NF | D4: Carta de Entrega da Nota Fiscal | E4: CARTA_NOTA_FISCAL | F4: Fiscal | G4: Mensal | H4: Contrato | I4: Bloqueante | J4: FINANCEIRO | K4: Mês da Competência | L4: Mês da competência | M4: SOB FATURAMENTO | N4: Ateste do cliente | O4: Corrido | P4: 0 | Q4: CLOUD/JIRA | R4: OPERAÇÃO | S4: Mensalmente | T4: Edital
A5: L004 | B5: BNB | C5: FIS.NOTA_FISCAL | D5: Nota Fiscal | E5: NOTA _FISCAL | F5: Fiscal | G5: Mensal | H5: Contrato | I5: Bloqueante | J5: FINANCEIRO | K5: Mês da Competência | L5: Mês da competência | M5: SOB FATURAMENTO | N5: Ateste do cliente | O5: Corrido | P5: 0 | Q5: CLOUD/JIRA | R5: OPERAÇÃO | S5: Mensalmente | T5: Edital | V5: NOMENCLATURA com espaço/caractere irregular
A6: L005 | B6: BNB | C6: CER.CND_RFB | D6: Certidão expedida pela Secretaria da Receita Federal do Brasil – RFB | E6: CND_RFB | F6: Certidões e regularidade | G6: Mensal | H6: Contrato | I6: Bloqueante | J6: FINANCEIRO | K6: Mês da Competência | L6: Válida na data do faturamento | M6: SOB FATURAMENTO | N6: Ateste do cliente | O6: Corrido | P6: 0 | Q6: CLOUD | R6: CERTIDÕES | S6: Mensalmente | T6: Edital
A7: L006 | B7: BNB | C7: CER.CRF_FGTS | D7: Certificado de Regularidade do Fundo de Garantia por Tempo de Serviço – FGTS | E7: CRF_FGTS | F7: Certidões e regularidade | G7: Mensal | H7: Contrato | I7: Bloqueante | J7: FINANCEIRO | K7: Mês da Competência | L7: Válida na data do faturamento | M7: SOB FATURAMENTO | N7: Ateste do cliente | O7: Corrido | P7: 0 | Q7: CLOUD | R7: CERTIDÕES | S7: Mensalmente | T7: Edital
A8: L007 | B8: BNB | C8: CER.CNDT | D8: Certidão Negativa de Débitos Trabalhistas – CNDT | E8: CNDT | F8: Certidões e regularidade | G8: Mensal | H8: Contrato | I8: Bloqueante | J8: FINANCEIRO | K8: Mês da Competência | L8: Válida na data do faturamento | M8: SOB FATURAMENTO | N8: Ateste do cliente | O8: Corrido | P8: 0 | Q8: CLOUD | R8: CERTIDÕES | S8: Mensalmente | T8: Edital
A9: L008 | B9: BNB | C9: CER.SICAF | D9: Sistema de Cadastramento Unificado de Fornecedores - SICAF | E9: SICAF | F9: Certidões e regularidade | G9: Mensal | H9: Contrato | I9: Bloqueante | J9: FINANCEIRO | K9: Mês da Competência | L9: Válida na data do faturamento | M9: SOB FATURAMENTO | N9: Ateste do cliente | O9: Corrido | P9: 0 | Q9: CLOUD | R9: CERTIDÕES | S9: Mensalmente | T9: Edital
A10: L009 | B10: BNB | C10: CER.CND_ESTADUAL | D10: Certidão Positiva de Débitos Com Efeito de Negativa - GDF | E10: CND_GDF | F10: Certidões e regularidade | G10: Mensal | H10: Contrato | I10: Bloqueante | J10: FINANCEIRO | K10: Mês da Competência | L10: Válida na data do faturamento | M10: SOB FATURAMENTO | N10: Ateste do cliente | O10: Corrido | P10: 0 | Q10: CLOUD | R10: CERTIDÕES | S10: Mensalmente | T10: Edital
A11: L010 | B11: BNB | C11: CER.CND_CIVEL_CRIMINAL | D11: Certidão Negativa de Distribuição (Especial Ações Cíveis e Criminais) | E11: CND_CÍVEL_E_CRIMINAL | F11: Certidões e regularidade | G11: Mensal | H11: Contrato | I11: Bloqueante | J11: FINANCEIRO | K11: Mês da Competência | L11: Válida na data do faturamento | M11: SOB FATURAMENTO | N11: Ateste do cliente | O11: Corrido | P11: 0 | Q11: CLOUD | R11: CERTIDÕES | S11: Mensalmente | T11: Edital
A12: L011 | B12: BNB | C12: CER.CND_FALENCIA | D12: Certidão Negativa de Distribuição (Ações de Falências e Recuperações Judiciais) | E12: CND_FALENCIA_E_RECUP_JUD | F12: Certidões e regularidade | G12: Mensal | H12: Contrato | I12: Bloqueante | J12: FINANCEIRO | K12: Mês da Competência | L12: Válida na data do faturamento | M12: SOB FATURAMENTO | N12: Ateste do cliente | O12: Corrido | P12: 0 | Q12: CLOUD | R12: CERTIDÕES | S12: Mensalmente | T12: Edital
A13: L012 | B13: BNB | C13: FGT.GUIA | D13: Guia FGTS | E13: GFD_GUIA_DO_FGTS | F13: FGTS | G13: Mensal | H13: Contrato | I13: Bloqueante | J13: DP | K13: Mês da Competência | L13: Competência anterior (M-1) | M13: ATÉ DIA 20 | N13: Início da competência | O13: Corrido | P13: 20 | Q13: CLOUD | R13: FGTS | S13: Mensalmente | T13: Edital | V13: COMPETÊNCIA divergente: consta "Mês da Competência", esperado "Competência Anterior"
A14: L013 | B14: BNB | C14: FGT.COMPROVANTE_PG | D14: COMPROVANTE DE PAGAMENTO FGTS | E14: COMPROVANTE_PG_FGTS | F14: FGTS | G14: Mensal | H14: Contrato | I14: Bloqueante | J14: FINANCEIRO | K14: Competência Anterior | L14: Competência anterior (M-1) | M14: ATÉ DIA 21 | N14: Início da competência | O14: Corrido | P14: 21 | Q14: CLOUD | R14: FGTS | S14: Mensalmente | T14: Edital
A15: L014 | B15: BNB | C15: INS.DCTFWEB | D15: DCTFWEB Completa DARF | E15: DCTFWEB_COMPLETA | F15: INSS e tributos | G15: Mensal | H15: Contrato | I15: Bloqueante | J15: DP | K15: Competência Anterior | L15: Competência anterior (M-1) | M15: ATÉ DIA 20 | N15: Início da competência | O15: Corrido | P15: 20 | Q15: CLOUD | R15: INSS | S15: Mensalmente | T15: Edital
A16: L015 | B16: BNB | C16: INS.COMPROVANTE_PG | D16: Recolhimento e Comprovante de Pagamento | E16: COMPROVANTE_PG_INSS | F16: INSS e tributos | G16: Mensal | H16: Contrato | I16: Bloqueante | J16: FINANCEIRO | K16: Competência Anterior | L16: Competência anterior (M-1) | M16: ENTRE DIA 20 A 30 | N16: Início da competência | O16: Corrido | P16: 30 | Q16: CLOUD | R16: INSS | S16: Mensalmente | T16: Edital | V16: LINHA COMPOSTA: descreve mais de um artefato
A17: L016 | B17: BNB | C17: FOL.FOPAG | D17: Folha de Pagamento | E17: FOPAG | F17: Folha | G17: Mensal | H17: Contrato | I17: Bloqueante | J17: DP | K17: Mês da Competência | L17: Mês da competência | M17: ATÉ O 5º DIA ÚTIL | N17: Início da competência | O17: Útil | P17: 5 | Q17: CLOUD | R17: FOLHA | S17: Mensalmente | T17: Edital
A18: L017 | B18: BNB | C18: FOL.COMPROVANTE_PG | D18: Comprovante da Folha de Pagamento | E18: COMPROVANTE_PG_FOLHA | F18: Folha | G18: Mensal | H18: Contrato | I18: Bloqueante | J18: FINANCEIRO | K18: Mês da Competência | L18: Mês da competência | M18: 5º DIA UTIL | N18: Início da competência | O18: Útil | P18: 5 | Q18: CLOUD | R18: FOLHA | S18: Mensalmente | T18: Edital
A19: L018 | B19: BNB | C19: FOL.CONTRACHEQUE | D19: Contra Cheque | E19: CONTRACHEQUES | F19: Folha | G19: Mensal | H19: Profissional | I19: Bloqueante | J19: DP | K19: Mês da Competência | L19: Mês da competência | M19: ATÉ DIA 07 | N19: Início da competência | O19: Corrido | P19: 7 | Q19: CLOUD | R19: FOLHA | S19: Mensalmente | T19: Edital
A20: L019 | B20: CEF | C20: OPE.RELACAO_ALOCADOS | D20: RELAÇÃO DOS EMPREGADOS ALOCADOS NO CONTRATO PARA PRESTAÇÃO DE SERVIÇOS (PLANILHA CLT - MODELO ENCAMINHADO) | E20: RELAÇÃO_DOS_EMPREGADOS_ALOCADOS_NO_CONTRATO_PARA_PRESTAÇÃO_DE_SERVIÇOS | F20: Operação e medição | G20: Mensal | H20: Contrato | I20: Bloqueante | J20: OPERAÇÃO | K20: Mês da Competência | L20: Mês da competência | M20: DIA 25 DO MÊS | N20: Início da competência | O20: Corrido | P20: 25 | Q20: JIRA | S20: Mensalmente | T20: Até último dia útil
A21: L020 | B21: CEF | C21: OPE.EMPENHO | D21: Empenho | E21: EMPENHO | F21: Operação e medição | G21: Mensal | H21: Contrato | I21: Bloqueante | J21: OPERAÇÃO | K21: Mês da Competência | L21: Mês da competência | M21: DIA 25 DO MÊS | N21: Início da competência | O21: Corrido | P21: 25 | Q21: JIRA | S21: Mensalmente | T21: Até último dia útil
A22: L021 | B22: CEF | C22: FIS.CARTA_ENTREGA_NF | D22: Carta de Entrega da Nota Fiscal | E22: CARTA_NOTA_FISCAL | F22: Fiscal | G22: Mensal | H22: Contrato | I22: Bloqueante | J22: FINANCEIRO | K22: Mês da Competência | L22: Mês da competência | M22: SOB FATURAMENTO | N22: Ateste do cliente | O22: Corrido | P22: 0 | Q22: CLOUD/JIRA | R22: OPERAÇÃO | S22: Mensalmente | T22: Edital
A23: L022 | B23: CEF | C23: FIS.NOTA_FISCAL | D23: Nota Fiscal | E23: NOTA _FISCAL | F23: Fiscal | G23: Mensal | H23: Contrato | I23: Bloqueante | J23: FINANCEIRO | K23: Mês da Competência | L23: Mês da competência | M23: SOB FATURAMENTO | N23: Ateste do cliente | O23: Corrido | P23: 0 | Q23: CLOUD/JIRA | R23: OPERAÇÃO | S23: Mensalmente | T23: Edital | V23: NOMENCLATURA com espaço/caractere irregular
A24: L023 | B24: CEF | C24: FGT.GUIA | D24: Guia FGTS | E24: GFD-GUIA_DO_FGTS | F24: FGTS | G24: Mensal | H24: Contrato | I24: Bloqueante | J24: DP | K24: Competência Anterior | L24: Competência anterior (M-1) | M24: ATÉ DIA 20 | N24: Início da competência | O24: Corrido | P24: 20 | Q24: CLOUD | R24: FGTS | S24: Mensalmente | T24: Edital
A25: L024 | B25: CEF | C25: FGT.COMPROVANTE_PG | D25: COMPROVANTE DE PAGAMENTO FGTS | E25: COMPROVANTE_PG_FGTS | F25: FGTS | G25: Mensal | H25: Contrato | I25: Bloqueante | J25: FINANCEIRO | K25: Competência Anterior | L25: Competência anterior (M-1) | M25: DIA 21 | N25: Início da competência | O25: Corrido | P25: 21 | Q25: CLOUD | R25: FGTS | S25: Mensalmente | T25: Edital
A26: L025 | B26: CEF | C26: FGT.RELATORIO_DIGITAL | D26: FGTS DIGITAL - RELATÓRIOS | E26: FGTS-DETALHE_DA_GUIA | F26: FGTS | G26: Mensal | H26: Profissional | I26: Bloqueante | J26: DP | K26: Competência Anterior | L26: Competência anterior (M-1) | M26: ATÉ DIA 20 | N26: Início da competência | O26: Corrido | P26: 20 | Q26: CLOUD | R26: PARCELAMENTOS | S26: Mensalmente | T26: Edital | V26: PASTA incompatível com a família do documento
A27: L026 | B27: CEF | C27: INS.PARCELAMENTO_TABELA | D27: TABELA RESUMO DOS PARCELAMENTOS INSS EM ANDAMENTO | E27: TABELA_RESUMO_PARCELAMENTOS | F27: INSS e tributos | G27: Mensal | H27: Contrato | I27: Não bloqueante | J27: FINANCEIRO | K27: Competência Anterior | L27: Competência anterior (M-1) | M27: ENTRE DIA 30 A 31 | N27: Início da competência | O27: Corrido | P27: 31 | Q27: CLOUD | R27: PARCELAMENTOS | S27: Mensalmente | T27: Edital
A28: L027 | B28: CEF | C28: INS.PARCELAMENTO_COMPROV | D28: DARFS E COMPROVANTES DOS PARCELAMENTOS INSS EM ANDAMENTO | E28: COMPROVANTES_PARCELAMENTOS | F28: INSS e tributos | G28: Mensal | H28: Contrato | I28: Bloqueante | J28: FINANCEIRO | K28: Competência Anterior | L28: Competência anterior (M-1) | M28: ENTRE DIA 30 A 31 | N28: Início da competência | O28: Corrido | P28: 31 | Q28: CLOUD | R28: FGTS | S28: Mensalmente | T28: Edital | V28: LINHA COMPOSTA: descreve mais de um artefato | PASTA incompatível com a família do documento
A29: L028 | B29: CEF | C29: FER.AVISO | D29: Aviso de férias | E29: AVISO_DE_FERIAS | F29: Férias | G29: Férias | H29: Profissional | I29: Bloqueante | J29: DP | K29: Mês da Competência | L29: Data do evento | M29: ATÉ DIA 07 | N29: Início da competência | O29: Corrido | P29: 7 | Q29: CLOUD | R29: FÉRIAS | T29: Edital | V29: PERIODICIDADE em branco
A30: L029 | B30: CEF | C30: FER.RECIBO | D30: Recibo de férias | E30: RECIBO_DE_FÉRIAS | F30: Férias | G30: Férias | H30: Profissional | I30: Bloqueante | J30: DP | K30: Mês da Competência | L30: Data do evento | M30: ATÉ DIA 07 | N30: Início da competência | O30: Corrido | P30: 7 | Q30: CLOUD | R30: FÉRIAS | V30: PERIODICIDADE em branco | PREVISÃO/fundamento em branco
A31: L030 | B31: CEF | C31: FER.COMPROVANTE_PG | D31: FÉRIAS - COMPROVANTE DE PAGAMENTO | E31: COMPROVANTE_PG_FÉRIAS | F31: Férias | G31: Férias | H31: Profissional | I31: Bloqueante | J31: FINANCEIRO | K31: Mês da Competência | L31: Data do evento | M31: 1º DIA ÚTIL | N31: Início da competência | O31: Útil | P31: 1 | Q31: CLOUD | R31: FÉRIAS | S31: Mensalmente | T31: Edital
A32: L031 | B32: CEF | C32: BEN.RELACAO_VT | D32: VALE TRANSPORTE E COMPROVANTE DE PAGAMENTO OU TERMO DE NÃO ADESÃO | E32: RELAÇÃO_DE_VT | F32: Benefícios | G32: Mensal | H32: Profissional | I32: Bloqueante | J32: DP | K32: Mês da Competência | L32: Mês da competência | M32: ATÉ DIA 03 | N32: Início da competência | O32: Corrido | P32: 3 | Q32: CLOUD | R32: TRANSPORTE | S32: Mensalmente | T32: Edital | V32: LINHA COMPOSTA: descreve mais de um artefato
A33: L032 | B33: CEF | C33: BEN.TERMO_NAO_ADESAO_VT | D33: TERMO DE NÃO ADESÃO VT | E33: TERMO_DE_ADESÃO_VT | F33: Benefícios | G33: Eventual | H33: Profissional | I33: Não bloqueante | J33: DP | K33: Mês da Competência | L33: Data do evento | M33: ATÉ DIA 07 | N33: Início da competência | O33: Corrido | P33: 7 | Q33: CLOUD | R33: TRANSPORTE | S33: Mensalmente | V33: PREVISÃO/fundamento em branco | SEMÂNTICA INVERTIDA: código diz "adesão", documento é "NÃO adesão"
A34: L033 | B34: CEF | C34: BEN.COMPROVANTE_VT | E34: COMPROVANTE_PG_VT | F34: Benefícios | G34: Mensal | H34: Contrato | I34: Bloqueante | J34: FINANCEIRO | L34: Mês da competência | M34: ATÉ DIA 05 | N34: Início da competência | O34: Corrido | P34: 5 | Q34: CLOUD | R34: TRANSPORTE | V34: LINHA ÓRFÃ: sem contrato de origem | COMPETÊNCIA em branco | PERIODICIDADE em branco | PREVISÃO/fundamento em branco | DESCRIÇÃO do documento em branco
A35: L034 | B35: CEF | C35: RES.TRCT | D35: Termo de Rescisão | E35: TRCT | F35: Rescisão | G35: Rescisão | H35: Profissional | I35: Bloqueante | J35: DP | K35: Mês da Competência | L35: Data do evento | M35: ATÉ DIA 07 | N35: Início da competência | O35: Corrido | P35: 7 | Q35: CLOUD | R35: RESCISÃO | S35: Mensalmente | T35: Edital
A36: L035 | B36: CEF | C36: RES.ASO_DEMISSIONAL | D36: ASO - Demissional | E36: ASO_DEMISSIONAL | F36: Rescisão | G36: Rescisão | H36: Profissional | I36: Bloqueante | J36: DP | K36: Mês da Competência | L36: Data do evento | M36: ATÉ DIA 07 | N36: Início da competência | O36: Corrido | P36: 7 | Q36: CLOUD | R36: RESCISÃO | V36: PERIODICIDADE em branco | PREVISÃO/fundamento em branco
A37: L036 | B37: CEF | C37: RES.COMPROVANTE_PG | D37: Comprovante de pagamento TRCT | E37: COMPROVANTE_PG_RESCISÃO | F37: Rescisão | G37: Rescisão | H37: Profissional | I37: Bloqueante | J37: FINANCEIRO | K37: Mês da Competência | L37: Data do evento | M37: 10º dia útil | N37: Início da competência | O37: Útil | P37: 10 | Q37: CLOUD | R37: RESCISÃO | V37: DUPLICIDADE no mesmo contrato/evento | PERIODICIDADE em branco | PREVISÃO/fundamento em branco
A38: L037 | B38: CEF | C38: RES.AVISO_PREVIO | D38: Aviso previo | E38: AVISO_PREVIO | F38: Rescisão | G38: Rescisão | H38: Profissional | I38: Bloqueante | J38: DP | K38: Mês da Competência | L38: Data do evento | M38: ATÉ DIA 07 | N38: Início da competência | O38: Corrido | P38: 7 | Q38: CLOUD | R38: RESCISÃO | V38: PERIODICIDADE em branco | PREVISÃO/fundamento em branco
A39: L038 | B39: CEF | C39: FGT.EXTRATO | D39: Extrato FGTS | E39: EXTRATO_FGTS | F39: FGTS | G39: Mensal | H39: Profissional | I39: Bloqueante | J39: DP | K39: Competência Anterior | L39: Competência anterior (M-1) | M39: ATÉ DIA 25 | N39: Início da competência | O39: Corrido | P39: 25 | Q39: CLOUD | R39: FGTS | V39: PERIODICIDADE em branco | PREVISÃO/fundamento em branco
A40: L039 | B40: CEF | C40: FGT.GUIA_RESCISORIA | D40: Guia FGTS Rescisão | E40: GUIA_GFD | F40: FGTS | G40: Rescisão | H40: Profissional | I40: Bloqueante | J40: DP | K40: Mês da Competência | L40: Data do evento | M40: ATÉ DIA 07 | N40: Início da competência | O40: Corrido | P40: 7 | Q40: CLOUD | R40: FGTS | V40: PERIODICIDADE em branco | PREVISÃO/fundamento em branco
...

Sheet DIVERGENCIAS_POR_LINHA
A1: ID | B1: CONTRATO | C1: COD_CANONICO | D1: NOMENCLATURA_ORIGINAL | E1: DIVERGENCIA | F1: ACAO
A2: L004 | B2: BNB | C2: FIS.NOTA_FISCAL | D2: NOTA _FISCAL | E2: NOMENCLATURA com espaço/caractere irregular
A3: L012 | B3: BNB | C3: FGT.GUIA | D3: GFD_GUIA_DO_FGTS | E3: COMPETÊNCIA divergente: consta "Mês da Competência", esperado "Competência Anterior"
A4: L015 | B4: BNB | C4: INS.COMPROVANTE_PG | D4: COMPROVANTE_PG_INSS | E4: LINHA COMPOSTA: descreve mais de um artefato
A5: L022 | B5: CEF | C5: FIS.NOTA_FISCAL | D5: NOTA _FISCAL | E5: NOMENCLATURA com espaço/caractere irregular
A6: L025 | B6: CEF | C6: FGT.RELATORIO_DIGITAL | D6: FGTS-DETALHE_DA_GUIA | E6: PASTA incompatível com a família do documento
A7: L027 | B7: CEF | C7: INS.PARCELAMENTO_COMPROV | D7: COMPROVANTES_PARCELAMENTOS | E7: LINHA COMPOSTA: descreve mais de um artefato
A8: L027 | B8: CEF | C8: INS.PARCELAMENTO_COMPROV | D8: COMPROVANTES_PARCELAMENTOS | E8: PASTA incompatível com a família do documento
A9: L028 | B9: CEF | C9: FER.AVISO | D9: AVISO_DE_FERIAS | E9: PERIODICIDADE em branco
A10: L029 | B10: CEF | C10: FER.RECIBO | D10: RECIBO_DE_FÉRIAS | E10: PERIODICIDADE em branco
A11: L029 | B11: CEF | C11: FER.RECIBO | D11: RECIBO_DE_FÉRIAS | E11: PREVISÃO/fundamento em branco
A12: L031 | B12: CEF | C12: BEN.RELACAO_VT | D12: RELAÇÃO_DE_VT | E12: LINHA COMPOSTA: descreve mais de um artefato
A13: L032 | B13: CEF | C13: BEN.TERMO_NAO_ADESAO_VT | D13: TERMO_DE_ADESÃO_VT | E13: PREVISÃO/fundamento em branco
... A114: L176 | B114: TJ CE | C114: FGT.COMPROVANTE_PG | D114: COMPROVANTE_PG_FGTS | E114: PREVISÃO/fundamento em branco

Sheet COBERTURA
A1: Cobertura documental por contrato e família (contagem automática sobre a aba MATRIZ_EXIGIBILIDADE)
A2: Célula zerada = a família não é exigida naquele contrato. Confirmar se é correto ou se é lacuna do checklist (ver achado D09).
A4: FAMILIA | B4: BNB | C4: CEF | D4: DOCAS | E4: SEFAZ RS | F4: SESCOOP | G4: TERRACAP | H4: TJ CE | I4: Telebrás | J4: TOTAL
A5: 13º salário | B5: =COUNTIFS(MATRIZ_EXIGIBILIDADE!$B$2:$B$177,"BNB",MATRIZ_EXIGIBILIDADE!$F$2:$F$177,$A5) -> 0 | C5: =COUNTIFS(MATRIZ_EXIGIBILIDADE!$B$2:$B$177,"CEF",MATRIZ_EXIGIBILIDADE!$F$2:$F$177,$A5) -> 1 | D5: =COUNTIFS(MATRIZ_EXIGIBILIDADE!$B$2:$B$177,"DOCAS",MATRIZ_EXIGIBILIDADE!$F$2:$F$177,$A5) -> 0 | E5: =COUNTIFS(MATRIZ_EXIGIBILIDADE!$B$2:$B$177,"SEFAZ RS",MATRIZ_EXIGIBILIDADE!$F$2:$F$177,$A5) -> 0 | F5: =COUNTIFS(MATRIZ_EXIGIBILIDADE!$B$2:$B$177,"SESCOOP",MATRIZ_EXIGIBILIDADE!$F$2:$F$177,$A5) -> 0 | G5: =COUNTIFS(MATRIZ_EXIGIBILIDADE!$B$2:$B$177,"TERRACAP",MATRIZ_EXIGIBILIDADE!$F$2:$F$177,$A5) -> 0 | H5: =COUNTIFS(MATRIZ_EXIGIBILIDADE!$B$2:$B$177,"TJ CE",MATRIZ_EXIGIBILIDADE!$F$2:$F$177,$A5) -> 2 | I5: =COUNTIFS(MATRIZ_EXIGIBILIDADE!$B$2:$B$177,"Telebrás",MATRIZ_EXIGIBILIDADE!$F$2:$F$177,$A5) -> 0 | J5: =SUM(B5:I5) -> 3
A6: Admissão | B6: =COUNTIFS(MATRIZ_EXIGIBILIDADE!$B$2:$B$177,"BNB",MATRIZ_EXIGIBILIDADE!$F$2:$F$177,$A6) -> 0 | C6: =COUNTIFS(MATRIZ_EXIGIBILIDADE!$B$2:$B$177,"CEF",MATRIZ_EXIGIBILIDADE!$F$2:$F$177,$A6) -> 0 | D6: =COUNTIFS(MATRIZ_EXIGIBILIDADE!$B$2:$B$177,"DOCAS",MATRIZ_EXIGIBILIDADE!$F$2:$F$177,$A6) -> 0 | E6: =COUNTIFS(MATRIZ_EXIGIBILIDADE!$B$2:$B$177,"SEFAZ RS",MATRIZ_EXIGIBILIDADE!$F$2:$F$177,$A6) -> 0 | F6: =COUNTIFS(MATRIZ_EXIGIBILIDADE!$B$2:$B$177,"SESCOOP",MATRIZ_EXIGIBILIDADE!$F$2:$F$177,$A6) -> 0 | G6: =COUNTIFS(MATRIZ_EXIGIBILIDADE!$B$2:$B$177,"TERRACAP",MATRIZ_EXIGIBILIDADE!$F$2:$F$177,$A6) -> 0 | H6: =COUNTIFS(MATRIZ_EXIGIBILIDADE!$B$2:$B$177,"TJ CE",MATRIZ_EXIGIBILIDADE!$F$2:$F$177,$A6) -> 1 | I6: =COUNTIFS(MATRIZ_EXIGIBILIDADE!$B$2:$B$177,"Telebrás",MATRIZ_EXIGIBILIDADE!$F$2:$F$177,$A6) -> 0 | J6: =SUM(B6:I6) -> 1
A7: Benefícios | B7: =COUNTIFS(MATRIZ_EXIGIBILIDADE!$B$2:$B$177,"BNB",MATRIZ_EXIGIBILIDADE!$F$2:$F$177,$A7) -> 0 | C7: =COUNTIFS(MATRIZ_EXIGIBILIDADE!$B$2:$B$177,"CEF",MATRIZ_EXIGIBILIDADE!$F$2:$F$177,$A7) -> 5 | D7: =COUNTIFS(MATRIZ_EXIGIBILIDADE!$B$2:$B$177,"DOCAS",MATRIZ_EXIGIBILIDADE!$F$2:$F$177,$A7) -> 2 | E7: =COUNTIFS(MATRIZ_EXIGIBILIDADE!$B$2:$B$177,"SEFAZ RS",MATRIZ_EXIGIBILIDADE!$F$2:$F$177,$A7) -> 0 | F7: =COUNTIFS(MATRIZ_EXIGIBILIDADE!$B$2:$B$177,"SESCOOP",MATRIZ_EXIGIBILIDADE!$F$2:$F$177,$A7) -> 6 | G7: =COUNTIFS(MATRIZ_EXIGIBILIDADE!$B$2:$B$177,"TERRACAP",MATRIZ_EXIGIBILIDADE!$F$2:$F$177,$A7) -> 0 | H7: =COUNTIFS(MATRIZ_EXIGIBILIDADE!$B$2:$B$177,"TJ CE",MATRIZ_EXIGIBILIDADE!$F$2:$F$177,$A7) -> 2 | I7: =COUNTIFS(MATRIZ_EXIGIBILIDADE!$B$2:$B$177,"Telebrás",MATRIZ_EXIGIBILIDADE!$F$2:$F$177,$A7) -> 0 | J7: =SUM(B7:I7) -> 15
A8: Certidões e regularidade | B8: =COUNTIFS(MATRIZ_EXIGIBILIDADE!$B$2:$B$177,"BNB",MATRIZ_EXIGIBILIDADE!$F$2:$F$177,$A8) -> 7 | C8: =COUNTIFS(MATRIZ_EXIGIBILIDADE!$B$2:$B$177,"CEF",MATRIZ_EXIGIBILIDADE!$F$2:$F$177,$A8) -> 4 | D8: =COUNTIFS(MATRIZ_EXIGIBILIDADE!$B$2:$B$177,"DOCAS",MATRIZ_EXIGIBILIDADE!$F$2:$F$177,$A8) -> 8 | E8: =COUNTIFS(MATRIZ_EXIGIBILIDADE!$B$2:$B$177,"SEFAZ RS",MATRIZ_EXIGIBILIDADE!$F$2:$F$177,$A8) -> 7 | F8: =COUNTIFS(MATRIZ_EXIGIBILIDADE!$B$2:$B$177,"SESCOOP",MATRIZ_EXIGIBILIDADE!$F$2:$F$177,$A8) -> 0 | G8: =COUNTIFS(MATRIZ_EXIGIBILIDADE!$B$2:$B$177,"TERRACAP",MATRIZ_EXIGIBILIDADE!$F$2:$F$177,$A8) -> 7 | H8: =COUNTIFS(MATRIZ_EXIGIBILIDADE!$B$2:$B$177,"TJ CE",MATRIZ_EXIGIBILIDADE!$F$2:$F$177,$A8) -> 7 | I8: =COUNTIFS(MATRIZ_EXIGIBILIDADE!$B$2:$B$177,"Telebrás",MATRIZ_EXIGIBILIDADE!$F$2:$F$177,$A8) -> 7 | J8: =SUM(B8:I8) -> 47
A9: FGTS | B9: =COUNTIFS(MATRIZ_EXIGIBILIDADE!$B$2:$B$177,"BNB",MATRIZ_EXIGIBILIDADE!$F$2:$F$177,$A9) -> 2 | C9: =COUNTIFS(MATRIZ_EXIGIBILIDADE!$B$2:$B$177,"CEF",MATRIZ_EXIGIBILIDADE!$F$2:$F$177,$A9) -> 6 | D9: =COUNTIFS(MATRIZ_EXIGIBILIDADE!$B$2:$B$177,"DOCAS",MATRIZ_EXIGIBILIDADE!$F$2:$F$177,$A9) -> 2 | E9: =COUNTIFS(MATRIZ_EXIGIBILIDADE!$B$2:$B$177,"SEFAZ RS",MATRIZ_EXIGIBILIDADE!$F$2:$F$177,$A9) -> 0 | F9: =COUNTIFS(MATRIZ_EXIGIBILIDADE!$B$2:$B$177,"SESCOOP",MATRIZ_EXIGIBILIDADE!$F$2:$F$177,$A9) -> 4 | G9: =COUNTIFS(MATRIZ_EXIGIBILIDADE!$B$2:$B$177,"TERRACAP",MATRIZ_EXIGIBILIDADE!$F$2:$F$177,$A9) -> 0 | H9: =COUNTIFS(MATRIZ_EXIGIBILIDADE!$B$2:$B$177,"TJ CE",MATRIZ_EXIGIBILIDADE!$F$2:$F$177,$A9) -> 7 | I9: =COUNTIFS(MATRIZ_EXIGIBILIDADE!$B$2:$B$177,"Telebrás",MATRIZ_EXIGIBILIDADE!$F$2:$F$177,$A9) -> 0 | J9: =SUM(B9:I9) -> 21
A10: Fiscal | B10: =COUNTIFS(MATRIZ_EXIGIBILIDADE!$B$2:$B$177,"BNB",MATRIZ_EXIGIBILIDADE!$F$2:$F$177,$A10) -> 2 | C10: =COUNTIFS(MATRIZ_EXIGIBILIDADE!$B$2:$B$177,"CEF",MATRIZ_EXIGIBILIDADE!$F$2:$F$177,$A10) -> 2 | D10: =COUNTIFS(MATRIZ_EXIGIBILIDADE!$B$2:$B$177,"DOCAS",MATRIZ_EXIGIBILIDADE!$F$2:$F$177,$A10) -> 2 | E10: =COUNTIFS(MATRIZ_EXIGIBILIDADE!$B$2:$B$177,"SEFAZ RS",MATRIZ_EXIGIBILIDADE!$F$2:$F$177,$A10) -> 2 | F10: =COUNTIFS(MATRIZ_EXIGIBILIDADE!$B$2:$B$177,"SESCOOP",MATRIZ_EXIGIBILIDADE!$F$2:$F$177,$A10) -> 2 | G10: =COUNTIFS(MATRIZ_EXIGIBILIDADE!$B$2:$B$177,"TERRACAP",MATRIZ_EXIGIBILIDADE!$F$2:$F$177,$A10) -> 2 | H10: =COUNTIFS(MATRIZ_EXIGIBILIDADE!$B$2:$B$177,"TJ CE",MATRIZ_EXIGIBILIDADE!$F$2:$F$177,$A10) -> 2 | I10: =COUNTIFS(MATRIZ_EXIGIBILIDADE!$B$2:$B$177,"Telebrás",MATRIZ_EXIGIBILIDADE!$F$2:$F$177,$A10) -> 3 | J10: =SUM(B10:I10) -> 17
A11: Folha | B11: =COUNTIFS(MATRIZ_EXIGIBILIDADE!$B$2:$B$177,"BNB",MATRIZ_EXIGIBILIDADE!$F$2:$F$177,$A11) -> 3 | C11: =COUNTIFS(MATRIZ_EXIGIBILIDADE!$B$2:$B$177,"CEF",MATRIZ_EXIGIBILIDADE!$F$2:$F$177,$A11) -> 2 | D11: =COUNTIFS(MATRIZ_EXIGIBILIDADE!$B$2:$B$177,"DOCAS",MATRIZ_EXIGIBILIDADE!$F$2:$F$177,$A11) -> 3 | E11: =COUNTIFS(MATRIZ_EXIGIBILIDADE!$B$2:$B$177,"SEFAZ RS",MATRIZ_EXIGIBILIDADE!$F$2:$F$177,$A11) -> 0 | F11: =COUNTIFS(MATRIZ_EXIGIBILIDADE!$B$2:$B$177,"SESCOOP",MATRIZ_EXIGIBILIDADE!$F$2:$F$177,$A11) -> 3 | G11: =COUNTIFS(MATRIZ_EXIGIBILIDADE!$B$2:$B$177,"TERRACAP",MATRIZ_EXIGIBILIDADE!$F$2:$F$177,$A11) -> 0 | H11: =COUNTIFS(MATRIZ_EXIGIBILIDADE!$B$2:$B$177,"TJ CE",MATRIZ_EXIGIBILIDADE!$F$2:$F$177,$A11) -> 3 | I11: =COUNTIFS(MATRIZ_EXIGIBILIDADE!$B$2:$B$177,"Telebrás",MATRIZ_EXIGIBILIDADE!$F$2:$F$177,$A11) -> 0 | J11: =SUM(B11:I11) -> 14
A12: Férias | B12: =COUNTIFS(MATRIZ_EXIGIBILIDADE!$B$2:$B$177,"BNB",MATRIZ_EXIGIBILIDADE!$F$2:$F$177,$A12) -> 0 | C12: =COUNTIFS(MATRIZ_EXIGIBILIDADE!$B$2:$B$177,"CEF",MATRIZ_EXIGIBILIDADE!$F$2:$F$177,$A12) -> 3 | D12: =COUNTIFS(MATRIZ_EXIGIBILIDADE!$B$2:$B$177,"DOCAS",MATRIZ_EXIGIBILIDADE!$F$2:$F$177,$A12) -> 0 | E12: =COUNTIFS(MATRIZ_EXIGIBILIDADE!$B$2:$B$177,"SEFAZ RS",MATRIZ_EXIGIBILIDADE!$F$2:$F$177,$A12) -> 0 | F12: =COUNTIFS(MATRIZ_EXIGIBILIDADE!$B$2:$B$177,"SESCOOP",MATRIZ_EXIGIBILIDADE!$F$2:$F$177,$A12) -> 0 | G12: =COUNTIFS(MATRIZ_EXIGIBILIDADE!$B$2:$B$177,"TERRACAP",MATRIZ_EXIGIBILIDADE!$F$2:$F$177,$A12) -> 0 | H12: =COUNTIFS(MATRIZ_EXIGIBILIDADE!$B$2:$B$177,"TJ CE",MATRIZ_EXIGIBILIDADE!$F$2:$F$177,$A12) -> 5 | I12: =COUNTIFS(MATRIZ_EXIGIBILIDADE!$B$2:$B$177,"Telebrás",MATRIZ_EXIGIBILIDADE!$F$2:$F$177,$A12) -> 0 | J12: =SUM(B12:I12) -> 8
A13: INSS e tributos | B13: =COUNTIFS(MATRIZ_EXIGIBILIDADE!$B$2:$B$177,"BNB",MATRIZ_EXIGIBILIDADE!$F$2:$F$177,$A13) -> 2 | C13: =COUNTIFS(MATRIZ_EXIGIBILIDADE!$B$2:$B$177,"CEF",MATRIZ_EXIGIBILIDADE!$F$2:$F$177,$A13) -> 4 | D13: =COUNTIFS(MATRIZ_EXIGIBILIDADE!$B$2:$B$177,"DOCAS",MATRIZ_EXIGIBILIDADE!$F$2:$F$177,$A13) -> 2 | E13: =COUNTIFS(MATRIZ_EXIGIBILIDADE!$B$2:$B$177,"SEFAZ RS",MATRIZ_EXIGIBILIDADE!$F$2:$F$177,$A13) -> 0 | F13: =COUNTIFS(MATRIZ_EXIGIBILIDADE!$B$2:$B$177,"SESCOOP",MATRIZ_EXIGIBILIDADE!$F$2:$F$177,$A13) -> 4 | G13: =COUNTIFS(MATRIZ_EXIGIBILIDADE!$B$2:$B$177,"TERRACAP",MATRIZ_EXIGIBILIDADE!$F$2:$F$177,$A13) -> 0 | H13: =COUNTIFS(MATRIZ_EXIGIBILIDADE!$B$2:$B$177,"TJ CE",MATRIZ_EXIGIBILIDADE!$F$2:$F$177,$A13) -> 3 | I13: =COUNTIFS(MATRIZ_EXIGIBILIDADE!$B$2:$B$177,"Telebrás",MATRIZ_EXIGIBILIDADE!$F$2:$F$177,$A13) -> 0 | J13: =SUM(B13:I13) -> 15
A14: Operação e medição | B14: =COUNTIFS(MATRIZ_EXIGIBILIDADE!$B$2:$B$177,"BNB",MATRIZ_EXIGIBILIDADE!$F$2:$F$177,$A14) -> 2 | C14: =COUNTIFS(MATRIZ_EXIGIBILIDADE!$B$2:$B$177,"CEF",MATRIZ_EXIGIBILIDADE!$F$2:$F$177,$A14) -> 2 | D14: =COUNTIFS(MATRIZ_EXIGIBILIDADE!$B$2:$B$177,"DOCAS",MATRIZ_EXIGIBILIDADE!$F$2:$F$177,$A14) -> 5 | E14: =COUNTIFS(MATRIZ_EXIGIBILIDADE!$B$2:$B$177,"SEFAZ RS",MATRIZ_EXIGIBILIDADE!$F$2:$F$177,$A14) -> 2 | F14: =COUNTIFS(MATRIZ_EXIGIBILIDADE!$B$2:$B$177,"SESCOOP",MATRIZ_EXIGIBILIDADE!$F$2:$F$177,$A14) -> 2 | G14: =COUNTIFS(MATRIZ_EXIGIBILIDADE!$B$2:$B$177,"TERRACAP",MATRIZ_EXIGIBILIDADE!$F$2:$F$177,$A14) -> 3 | H14: =COUNTIFS(MATRIZ_EXIGIBILIDADE!$B$2:$B$177,"TJ CE",MATRIZ_EXIGIBILIDADE!$F$2:$F$177,$A14) -> 4 | I14: =COUNTIFS(MATRIZ_EXIGIBILIDADE!$B$2:$B$177,"Telebrás",MATRIZ_EXIGIBILIDADE!$F$2:$F$177,$A14) -> 2 | J14: =SUM(B14:I14) -> 22
A15: Rescisão | B15: =COUNTIFS(MATRIZ_EXIGIBILIDADE!$B$2:$B$177,"BNB",MATRIZ_EXIGIBILIDADE!$F$2:$F$177,$A15) -> 0 | C15: =COUNTIFS(MATRIZ_EXIGIBILIDADE!$B$2:$B$177,"CEF",MATRIZ_EXIGIBILIDADE!$F$2:$F$177,$A15) -> 5 | D15: =COUNTIFS(MATRIZ_EXIGIBILIDADE!$B$2:$B$177,"DOCAS",MATRIZ_EXIGIBILIDADE!$F$2:$F$177,$A15) -> 0 | E15: =COUNTIFS(MATRIZ_EXIGIBILIDADE!$B$2:$B$177,"SEFAZ RS",MATRIZ_EXIGIBILIDADE!$F$2:$F$177,$A15) -> 0 | F15: =COUNTIFS(MATRIZ_EXIGIBILIDADE!$B$2:$B$177,"SESCOOP",MATRIZ_EXIGIBILIDADE!$F$2:$F$177,$A15) -> 3 | G15: =COUNTIFS(MATRIZ_EXIGIBILIDADE!$B$2:$B$177,"TERRACAP",MATRIZ_EXIGIBILIDADE!$F$2:$F$177,$A15) -> 0 | H15: =COUNTIFS(MATRIZ_EXIGIBILIDADE!$B$2:$B$177,"TJ CE",MATRIZ_EXIGIBILIDADE!$F$2:$F$177,$A15) -> 5 | I15: =COUNTIFS(MATRIZ_EXIGIBILIDADE!$B$2:$B$177,"Telebrás",MATRIZ_EXIGIBILIDADE!$F$2:$F$177,$A15) -> 0 | J15: =SUM(B15:I15) -> 13
A16: TOTAL | B16: =SUM(B5:B15) -> 18 | C16: =SUM(C5:C15) -> 34 | D16: =SUM(D5:D15) -> 24 | E16: =SUM(E5:E15) -> 11 | F16: =SUM(F5:F15) -> 24 | G16: =SUM(G5:G15) -> 12 | H16: =SUM(H5:H15) -> 41 | I16: =SUM(I5:I15) -> 12 | J16: =SUM(J5:J15) -> 176

Sheet REGRAS_CONCILIACAO
A1: ID | B1: Regra | C1: Fontes cruzadas | D1: Falha que detecta | E1: Severidade | F1: Tolerância (preencher) | G1: Exceções previstas (preencher)
A2: R01 | B2: Cobertura do plano de saúde | C2: BEN.RELACAO_PLANO_SAUDE x rubrica de desconto na FOL.FOPAG x BEN.COMPROVANTE_PLANO_SAUDE | D2: Profissional na relação sem desconto em folha, ou desconto sem cobertura | E2: Bloqueante
A3: R02 | B3: Cobertura do FGTS | C3: FOL.FOPAG (base) x FGT.GUIA x FGT.EXTRATO x FGT.COMPROVANTE_PG | D3: Recolhimento sem individualização por trabalhador; base divergente | E3: Bloqueante
A4: R03 | B4: Cobertura do INSS | C4: FOL.FOPAG x INS.DCTFWEB x INS.DARF x INS.COMPROVANTE_PG | D4: Guia paga em valor diferente do apurado na folha | E4: Bloqueante
A5: R04 | B5: Completude da equipe | C5: OPE.RELACAO_ALOCADOS x FOL.FOPAG x FOL.CONTRACHEQUE (por profissional) | D5: Profissional faturado sem evidência de vínculo ou pagamento | E5: Bloqueante
A6: R05 | B6: Aderência da medição | C6: OPE.RELATORIO_MEDICAO x OPE.FOLHA_PONTO x OPE.PLANILHA_MEDICAO | D6: Horas/postos faturados sem lastro de medição | E6: Bloqueante
A7: R06 | B7: Vigência das certidões | C7: CER.* com data de validade na data de emissão da NF | D7: Certidão vencida no momento do ateste ou da emissão | E7: Bloqueante
A8: R07 | B8: Cobertura de VA/VR e VT | C8: BEN.RELACAO_* x desconto/crédito na folha x comprovante x termo de não adesão | D8: Benefício pago sem relação, ou relação sem comprovante | E8: Bloqueante
A9: R08 | B9: Fechamento de eventos de rescisão | C9: RES.TRCT x RES.COMPROVANTE_PG x FGT.GUIA_RESCISORIA x RES.ASO_DEMISSIONAL | D9: Rescisão no período sem conjunto documental completo | E9: Bloqueante
A10: R09 | B10: Fechamento de férias | C10: FER.AVISO x FER.RECIBO x FER.COMPROVANTE_PG x FOL.FOPAG | D10: Férias concedidas sem recibo ou sem comprovante de pagamento | E10: Bloqueante
A11: R10 | B11: Defasagem de competência | C11: Todo documento de FGTS/INSS/IRRF deve referir-se a M-1 | D11: Documento anexado da competência errada | E11: Bloqueante
A12: R11 | B12: Vinculação ao empenho | C12: OPE.EMPENHO x valor da OPE.PLANILHA_MEDICAO x FIS.NOTA_FISCAL | D12: Faturamento acima do saldo de empenho | E12: Bloqueante
A13: R12 | B13: Relógio D+3 | C13: OPE.ATESTE_RECEBIMENTO (data) x FIS.NOTA_FISCAL (data de emissão) | D13: Descumprimento da meta institucional de emissão em D+3 | E13: Indicador

Sheet CAMPOS_A_CRIAR
A1: ID | B1: Campo | C1: Para que serve | D1: Origem do valor | E1: Consequência de não ter
A2: C01 | B2: EVENTO | C2: Distinguir mensal, 13º, férias, rescisão e admissão | D2: Cadastro do tipo documental | E2: Documentos de eventos diferentes competem pela mesma linha do checklist
A3: C02 | B3: GRANULARIDADE | C3: Saber se a exigência é por contrato ou por profissional | D3: Cadastro do tipo documental | E3: Impossível calcular completude ("faltam 3 de 42")
A4: C03 | B4: CRITICIDADE | C4: Separar o que bloqueia o faturamento do que é regularizável | D4: Decisão da DAF por contrato | E4: Ou tudo bloqueia, ou nada bloqueia
A5: C04 | B5: COMPETENCIA_REFERENCIA | C5: Defasagem do documento em relação à competência faturada | D5: Regra legal por tipo documental | E5: Busca do documento no mês errado
A6: C05 | B6: PRAZO_ANCORA / TIPO_DIA / LIMITE | C6: Tornar o prazo computável e medir SLA por área | D6: Conversão do texto atual + calendário de feriados | E6: Sem alerta automático e sem apuração de atraso
A7: C06 | B7: FUNDAMENTO | C7: Cláusula do edital/contrato ou norma que origina a exigência | D7: Leitura do contrato pela área de Contratos | E7: Sem rastreabilidade perante o cliente e órgãos de controle
A8: C07 | B8: REPOSITORIO_MESTRE | C8: Definir onde está a evidência oficial (Cloud x Jira) | D8: Decisão de TI + DAF | E8: Conferência depende de onde a pessoa procurou
A9: C08 | B9: CONDICIONALIDADE | C9: Expressar regras "A ou B" (ex.: relação de VT ou termo de não adesão) | D9: Cadastro do tipo documental | E9: Pendência falsa em situações legítimas
A10: C09 | B10: VIGENCIA_INICIO / VIGENCIA_FIM | C10: Registrar quando a exigência passou a valer (aditivos) | D10: Gestão contratual | E10: Reprocessar competência antiga com a regra errada
A11: C10 | B11: CLASSIFICACAO_SIGILO | C11: Marcar o que contém dado pessoal ou sensível e o que pode ir ao cliente | D11: Política de classificação da informação | E11: Envio de dado além do necessário ao cliente (LGPD, art. 6º, III)
A12: C11 | B12: RESPONSAVEL_SUBSTITUTO | C12: Escalonamento quando o responsável primário não atua no prazo | D12: Estrutura das áreas | E12: Pendência parada sem escalonamento
A13: C12 | B13: EVENTO_ATESTE | C13: Data e forma do ateste formal do cliente | D13: Operação / gestor do contrato | E13: O D+3 da política não é apurável de forma objetiva
